// test for exception handler

#include <stdio.h>

void throwException(int);
void cancelCatchException(void);
int catchException(void);

void f3()
{
  fprintf(stderr, "f3 entered\n");
  throwException(1999);
  fprintf(stderr, "f3 exiting\n");
}

void f2()
{
  fprintf(stderr, "f2 entered\n");
  f3();
  fprintf(stderr, "f2 exiting\n");
}

void f1()
{
  fprintf(stderr, "f1 entered\n");
  f2();
  fprintf(stderr, "f1 exiting\n");
}

int main(int argc, char*argv[])
{
  int caughtException;

  fprintf(stderr, "main entered\n");
  if ((caughtException = catchException()))
  {
    fprintf(stderr, "catch clause entered\n");
    fprintf(stderr, "caught exception %d\n", caughtException);
    fprintf(stderr, "catch clause exiting\n");
  }
  else
  {
    fprintf(stderr, "try block entered\n");
    f1();
    cancelCatchException();
    fprintf(stderr, "try block exiting\n");
  }
  fprintf(stderr, "main exiting\n");
  cancelCatchException();
  throwException(1);
  return 0;
}

